{"content": {"suites": {"0": {"status": {"total_pass": 8, "total_skip": 0, "total_xpass": 0, "total_xfail": 0, "total_rerun": 0, "total_fail": 16, "total_error": 0}, "tests": {"0": {"status": "FAIL", "message": "           pika.exceptions.IncompatibleProtocolError: StreamLostError: ('Transport indicated EOF',)\n", "test_name": "test_create_order_successfully", "rerun": "0"}, "1": {"status": "FAIL", "message": "           pika.exceptions.IncompatibleProtocolError: StreamLostError: ('Transport indicated EOF',)\n", "test_name": "test_create_order_with_out_stock", "rerun": "0"}, "2": {"status": "FAIL", "message": "           pika.exceptions.IncompatibleProtocolError: StreamLostError: ('Transport indicated EOF',)\n", "test_name": "test_create_order_payment_rejected", "rerun": "0"}, "3": {"status": "FAIL", "message": "           pika.exceptions.IncompatibleProtocolError: StreamLostError: ('Transport indicated EOF',)\n", "test_name": "test_update_from_status_1", "rerun": "0"}, "4": {"status": "FAIL", "message": "           pika.exceptions.IncompatibleProtocolError: StreamLostError: ('Transport indicated EOF',)\n", "test_name": "test_update_from_status_2", "rerun": "0"}, "5": {"status": "FAIL", "message": "           pika.exceptions.IncompatibleProtocolError: StreamLostError: ('Transport indicated EOF',)\n", "test_name": "test_update_from_status_3", "rerun": "0"}, "6": {"status": "FAIL", "message": "           pika.exceptions.IncompatibleProtocolError: StreamLostError: ('Transport indicated EOF',)\n", "test_name": "test_update_from_status_4", "rerun": "0"}, "7": {"status": "FAIL", "message": "           pika.exceptions.IncompatibleProtocolError: StreamLostError: ('Transport indicated EOF',)\n", "test_name": "test_update_from_status_6", "rerun": "0"}, "8": {"status": "FAIL", "message": "           pika.exceptions.IncompatibleProtocolError: StreamLostError: ('Transport indicated EOF',)\n", "test_name": "test_cancel_from_status_1", "rerun": "0"}, "9": {"status": "FAIL", "message": "           pika.exceptions.IncompatibleProtocolError: StreamLostError: ('Transport indicated EOF',)\n", "test_name": "test_cancel_from_status_2", "rerun": "0"}, "10": {"status": "FAIL", "message": "           pika.exceptions.IncompatibleProtocolError: StreamLostError: ('Transport indicated EOF',)\n", "test_name": "test_cancel_from_status_3", "rerun": "0"}, "11": {"status": "FAIL", "message": "           pika.exceptions.IncompatibleProtocolError: StreamLostError: ('Transport indicated EOF',)\n", "test_name": "test_cancel_from_status_4", "rerun": "0"}, "12": {"status": "FAIL", "message": "           pika.exceptions.IncompatibleProtocolError: StreamLostError: ('Transport indicated EOF',)\n", "test_name": "test_cancel_from_status_5", "rerun": "0"}, "13": {"status": "FAIL", "message": "           pika.exceptions.IncompatibleProtocolError: StreamLostError: ('Transport indicated EOF',)\n", "test_name": "test_create_order_when_user_not_exist_in_db", "rerun": "0"}, "14": {"status": "FAIL", "message": "           pika.exceptions.IncompatibleProtocolError: StreamLostError: ('Transport indicated EOF',)\n", "test_name": "test_create_order_when_there_is_no_zipcode", "rerun": "0"}, "15": {"status": "FAIL", "message": "           pika.exceptions.IncompatibleProtocolError: StreamLostError: ('Transport indicated EOF',)\n", "test_name": "test_create_new_order_card_number_only_chars", "rerun": "0"}, "16": {"status": "PASS", "message": "", "test_name": "test_create_order_when_cardTypeId_not_defind", "rerun": "0"}, "17": {"status": "PASS", "message": "", "test_name": "test_create_new_order_when_CardTypeId_only_chars", "rerun": "0"}, "18": {"status": "PASS", "message": "", "test_name": "test_create_new_order_when_CardSecuirtyNumber_only_chars", "rerun": "0"}, "19": {"status": "PASS", "message": "", "test_name": "test_create_new_order_with_zero_items", "rerun": "0"}, "20": {"status": "PASS", "message": "", "test_name": "test_create_new_order_with_productId_not_exist", "rerun": "0"}, "21": {"status": "PASS", "message": "", "test_name": "test_create_new_order_with_productId_only_chars", "rerun": "0"}, "22": {"status": "PASS", "message": "", "test_name": "test_create_new_order_with_negative_productId", "rerun": "0"}, "23": {"status": "PASS", "message": "", "test_name": "test_create_new_order_with_negative_price", "rerun": "0"}}, "suite_name": "test_Functional.py"}, "1": {"suite_name": "test_non_functional.py", "tests": {"0": {"status": "FAIL", "message": "   KeyError: 'eshop/ordering.api:linux-latest'\n", "test_name": "test_create_order_when_ordering_service_restarts", "rerun": "0"}, "1": {"status": "FAIL", "message": "   KeyError: 'eshop/ordering.api:linux-latest'\n   KeyError: 'eshop/ordering.api:linux-latest'\n", "test_name": "test_create_order_when_ordering_service_down", "rerun": "0"}, "2": {"status": "FAIL", "message": "       assert (200 + 10) == 200\n", "test_name": "test_create_100_new_orders", "rerun": "0"}}, "status": {"total_pass": 0, "total_skip": 0, "total_xpass": 0, "total_xfail": 0, "total_rerun": 0, "total_fail": 3, "total_error": 0}}, "2": {"suite_name": "test_smoke.py", "tests": {"0": {"status": "FAIL", "message": "           ConnectionRefusedError: [WinError 10061] No connection could be made because the target machine actively refused it\n       urllib3.exceptions.NewConnectionError: <urllib3.connection.HTTPConnection object at 0x0463FF30>: Failed to establish a new connection: [WinError 10061] No connection could be made because the target machine actively refused it\n       urllib3.exceptions.MaxRetryError: HTTPConnectionPool(host='host.docker.internal', port=5105): Max retries exceeded with url: /Account/Login?ReturnUrl=%2Fconnect%2Fauthorize%2Fcallback%3Fresponse_type%3Dtoken%26client_id%3Dorderingswaggerui%26redirect_uri%3Dhttp%253A%252F%252Fhost.docker.internal%253A5102%252Fswagger%252Foauth2-redirect.html%26scope%3Dorders%26state%3DTW9uIE1hciAwNiAyMDIzIDE1OjI5OjA4IEdNVCswMjAwIChJc3JhZWwgU3RhbmRhcmQgVGltZSk%253D (Caused by NewConnectionError('<urllib3.connection.HTTPConnection object at 0x0463FF30>: Failed to establish a new connection: [WinError 10061] No connection could be made because the target machine actively refused it'))\n       requests.exceptions.ConnectionError: HTTPConnectionPool(host='host.docker.internal', port=5105): Max retries exceeded with url: /Account/Login?ReturnUrl=%2Fconnect%2Fauthorize%2Fcallback%3Fresponse_type%3Dtoken%26client_id%3Dorderingswaggerui%26redirect_uri%3Dhttp%253A%252F%252Fhost.docker.internal%253A5102%252Fswagger%252Foauth2-redirect.html%26scope%3Dorders%26state%3DTW9uIE1hciAwNiAyMDIzIDE1OjI5OjA4IEdNVCswMjAwIChJc3JhZWwgU3RhbmRhcmQgVGltZSk%253D (Caused by NewConnectionError('<urllib3.connection.HTTPConnection object at 0x0463FF30>: Failed to establish a new connection: [WinError 10061] No connection could be made because the target machine actively refused it'))\n", "test_name": "test_order_response", "rerun": "0"}}, "status": {"total_pass": 0, "total_skip": 0, "total_xpass": 0, "total_xfail": 0, "total_rerun": 0, "total_fail": 1, "total_error": 0}}}}, "date": "March 18, 2023", "start_time": 1679167621.650645, "total_suite": 3, "status": "FAIL", "status_list": {"pass": "8", "fail": "20", "skip": "0", "error": "0", "xpass": "0", "xfail": "0", "rerun": "0"}, "total_tests": "28"}